Building DAG of jobs...
Using shell: /bin/bash
Provided cores: 16
Rules claiming more threads will be scaled down.
Job counts:
	count	jobs
	1	annovar_input
	1

[Sat Aug 29 11:25:24 2020]
rule annovar_input:
    input: /u/home/j/jzou1115/project-zarlab/CFW/confidence_interval_pipeline_out_pruned/finemapping/output/weight.13.9217096_snps.txt, /u/home/j/jzou1115/project-zarlab/CFW/confidence_interval_pipeline_out_pruned/locuszoom/weight.13.9217096_r2.txt
    output: /u/home/j/jzou1115/project-zarlab/CFW/confidence_interval_pipeline_out_pruned/finemapping/output/weight.13.9217096_annovar_input.txt
    jobid: 0
    wildcards: q=weight.13.9217096

Traceback (most recent call last):
  File "/u/project/zarlab/jzou1115/CFW/MegaAnalysis_CFW_Code/confidence_interval_pipeline_pruned/.snakemake/scripts/tmp2z20o87g.annovar_input.py", line 62, in <module>
    out = pd.concat(out, ignore_index=True)
  File "/u/home/j/jzou1115/project-ernst/software/anaconda3/lib/python3.7/site-packages/pandas/core/reshape/concat.py", line 281, in concat
    sort=sort,
  File "/u/home/j/jzou1115/project-ernst/software/anaconda3/lib/python3.7/site-packages/pandas/core/reshape/concat.py", line 329, in __init__
    raise ValueError("No objects to concatenate")
ValueError: No objects to concatenate
[Sat Aug 29 11:25:24 2020]
Error in rule annovar_input:
    jobid: 0
    output: /u/home/j/jzou1115/project-zarlab/CFW/confidence_interval_pipeline_out_pruned/finemapping/output/weight.13.9217096_annovar_input.txt

RuleException:
CalledProcessError in line 197 of /u/project/zarlab/jzou1115/CFW/MegaAnalysis_CFW_Code/confidence_interval_pipeline_pruned/Snakefile:
Command 'set -euo pipefail;  /u/home/j/jzou1115/project-ernst/software/anaconda3/bin/python3.7 /u/project/zarlab/jzou1115/CFW/MegaAnalysis_CFW_Code/confidence_interval_pipeline_pruned/.snakemake/scripts/tmp2z20o87g.annovar_input.py' returned non-zero exit status 1.
  File "/u/project/zarlab/jzou1115/CFW/MegaAnalysis_CFW_Code/confidence_interval_pipeline_pruned/Snakefile", line 197, in __rule_annovar_input
  File "/u/home/j/jzou1115/project-ernst/software/anaconda3/lib/python3.7/concurrent/futures/thread.py", line 57, in run
Shutting down, this might take some time.
Exiting because a job execution failed. Look above for error message
